[2025-02-09T01:16:23.222+0000] {local_task_job_runner.py:123} INFO - ::group::Pre task execution logs
[2025-02-09T01:16:23.265+0000] {taskinstance.py:2613} INFO - Dependencies all met for dep_context=non-requeueable deps ti=<TaskInstance: Execute_db_conection.run_meltano_script manual__2025-02-09T01:16:13.590804+00:00 [queued]>
[2025-02-09T01:16:23.285+0000] {taskinstance.py:2613} INFO - Dependencies all met for dep_context=requeueable deps ti=<TaskInstance: Execute_db_conection.run_meltano_script manual__2025-02-09T01:16:13.590804+00:00 [queued]>
[2025-02-09T01:16:23.293+0000] {taskinstance.py:2866} INFO - Starting attempt 1 of 2
[2025-02-09T01:16:23.683+0000] {taskinstance.py:2889} INFO - Executing <Task(PythonOperator): run_meltano_script> on 2025-02-09 01:16:13.590804+00:00
[2025-02-09T01:16:23.704+0000] {warnings.py:112} WARNING - /home/***/.local/lib/python3.12/site-packages/***/task/task_runner/standard_task_runner.py:70: DeprecationWarning: This process (pid=99) is multi-threaded, use of fork() may lead to deadlocks in the child.
  pid = os.fork()

[2025-02-09T01:16:23.720+0000] {standard_task_runner.py:72} INFO - Started process 101 to run task
[2025-02-09T01:16:23.727+0000] {standard_task_runner.py:104} INFO - Running: ['***', 'tasks', 'run', 'Execute_db_conection', 'run_meltano_script', 'manual__2025-02-09T01:16:13.590804+00:00', '--job-id', '151', '--raw', '--subdir', 'DAGS_FOLDER/connectBD_to_extract.py', '--cfg-path', '/tmp/tmp7hxr1mke']
[2025-02-09T01:16:23.733+0000] {standard_task_runner.py:105} INFO - Job 151: Subtask run_meltano_script
[2025-02-09T01:16:23.990+0000] {task_command.py:467} INFO - Running <TaskInstance: Execute_db_conection.run_meltano_script manual__2025-02-09T01:16:13.590804+00:00 [running]> on host dc93b884e523
[2025-02-09T01:16:24.224+0000] {taskinstance.py:3132} INFO - Exporting env vars: AIRFLOW_CTX_DAG_OWNER='***' AIRFLOW_CTX_DAG_ID='Execute_db_conection' AIRFLOW_CTX_TASK_ID='run_meltano_script' AIRFLOW_CTX_EXECUTION_DATE='2025-02-09T01:16:13.590804+00:00' AIRFLOW_CTX_TRY_NUMBER='1' AIRFLOW_CTX_DAG_RUN_ID='manual__2025-02-09T01:16:13.590804+00:00'
[2025-02-09T01:16:24.229+0000] {logging_mixin.py:190} INFO - Task instance is in running state
[2025-02-09T01:16:24.230+0000] {logging_mixin.py:190} INFO -  Previous state of the Task instance: queued
[2025-02-09T01:16:24.231+0000] {logging_mixin.py:190} INFO - Current task name:run_meltano_script state:running start_date:2025-02-09 01:16:23.267486+00:00
[2025-02-09T01:16:24.232+0000] {logging_mixin.py:190} INFO - Dag name:Execute_db_conection and current dag run status:running
[2025-02-09T01:16:24.234+0000] {taskinstance.py:731} INFO - ::endgroup::
[2025-02-09T01:16:24.328+0000] {taskinstance.py:3311} ERROR - Task failed with exception
Traceback (most recent call last):
  File "/home/airflow/.local/lib/python3.12/site-packages/airflow/models/taskinstance.py", line 767, in _execute_task
    result = _execute_callable(context=context, **execute_callable_kwargs)
             ^^^^^^^^^^^^^^^^^^^^^^^^^^^^^^^^^^^^^^^^^^^^^^^^^^^^^^^^^^^^^
  File "/home/airflow/.local/lib/python3.12/site-packages/airflow/models/taskinstance.py", line 733, in _execute_callable
    return ExecutionCallableRunner(
           ^^^^^^^^^^^^^^^^^^^^^^^^
  File "/home/airflow/.local/lib/python3.12/site-packages/airflow/utils/operator_helpers.py", line 252, in run
    return self.func(*args, **kwargs)
           ^^^^^^^^^^^^^^^^^^^^^^^^^^
  File "/home/airflow/.local/lib/python3.12/site-packages/airflow/models/baseoperator.py", line 422, in wrapper
    return func(self, *args, **kwargs)
           ^^^^^^^^^^^^^^^^^^^^^^^^^^^
  File "/home/airflow/.local/lib/python3.12/site-packages/airflow/operators/python.py", line 238, in execute
    return_value = self.execute_callable()
                   ^^^^^^^^^^^^^^^^^^^^^^^
  File "/home/airflow/.local/lib/python3.12/site-packages/airflow/operators/python.py", line 256, in execute_callable
    return runner.run(*self.op_args, **self.op_kwargs)
           ^^^^^^^^^^^^^^^^^^^^^^^^^^^^^^^^^^^^^^^^^^^
  File "/home/airflow/.local/lib/python3.12/site-packages/airflow/utils/operator_helpers.py", line 252, in run
    return self.func(*args, **kwargs)
           ^^^^^^^^^^^^^^^^^^^^^^^^^^
  File "/opt/airflow/dags/connectBD_to_extract.py", line 10, in run_meltano_script
    subprocess.run(["python", meltano_script_path], check=True)
  File "/usr/local/lib/python3.12/subprocess.py", line 571, in run
    raise CalledProcessError(retcode, process.args,
subprocess.CalledProcessError: Command '['python', '/opt/airflow/meltano_project/transform/extract_data_csv.py']' returned non-zero exit status 2.
[2025-02-09T01:16:24.375+0000] {logging_mixin.py:190} INFO - Task instance in failure state
[2025-02-09T01:16:24.377+0000] {logging_mixin.py:190} INFO - Task start:2025-02-09 01:16:23.267486+00:00 end:2025-02-09 01:16:24.374848+00:00 duration:1.107362
[2025-02-09T01:16:24.378+0000] {logging_mixin.py:190} INFO - Task:<Task(PythonOperator): run_meltano_script> dag:<DAG: Execute_db_conection> dagrun:<DagRun Execute_db_conection @ 2025-02-09 01:16:13.590804+00:00: manual__2025-02-09T01:16:13.590804+00:00, state:running, queued_at: 2025-02-09 01:16:13.664789+00:00. externally triggered: True>
[2025-02-09T01:16:24.379+0000] {logging_mixin.py:190} INFO - Failure caused by Command '['python', '/opt/***/meltano_project/transform/extract_data_csv.py']' returned non-zero exit status 2.
[2025-02-09T01:16:24.379+0000] {taskinstance.py:1225} INFO - Marking task as UP_FOR_RETRY. dag_id=Execute_db_conection, task_id=run_meltano_script, run_id=manual__2025-02-09T01:16:13.590804+00:00, execution_date=20250209T011613, start_date=20250209T011623, end_date=20250209T011624
[2025-02-09T01:16:24.423+0000] {taskinstance.py:340} INFO - ::group::Post task execution logs
[2025-02-09T01:16:24.425+0000] {standard_task_runner.py:124} ERROR - Failed to execute job 151 for task run_meltano_script (Command '['python', '/opt/airflow/meltano_project/transform/extract_data_csv.py']' returned non-zero exit status 2.; 101)
Traceback (most recent call last):
  File "/home/airflow/.local/lib/python3.12/site-packages/airflow/task/task_runner/standard_task_runner.py", line 117, in _start_by_fork
    ret = args.func(args, dag=self.dag)
          ^^^^^^^^^^^^^^^^^^^^^^^^^^^^^
  File "/home/airflow/.local/lib/python3.12/site-packages/airflow/cli/cli_config.py", line 49, in command
    return func(*args, **kwargs)
           ^^^^^^^^^^^^^^^^^^^^^
  File "/home/airflow/.local/lib/python3.12/site-packages/airflow/utils/cli.py", line 116, in wrapper
    return f(*args, **kwargs)
           ^^^^^^^^^^^^^^^^^^
  File "/home/airflow/.local/lib/python3.12/site-packages/airflow/cli/commands/task_command.py", line 483, in task_run
    task_return_code = _run_task_by_selected_method(args, _dag, ti)
                       ^^^^^^^^^^^^^^^^^^^^^^^^^^^^^^^^^^^^^^^^^^^^
  File "/home/airflow/.local/lib/python3.12/site-packages/airflow/cli/commands/task_command.py", line 256, in _run_task_by_selected_method
    return _run_raw_task(args, ti)
           ^^^^^^^^^^^^^^^^^^^^^^^
  File "/home/airflow/.local/lib/python3.12/site-packages/airflow/cli/commands/task_command.py", line 341, in _run_raw_task
    return ti._run_raw_task(
           ^^^^^^^^^^^^^^^^^
  File "/home/airflow/.local/lib/python3.12/site-packages/airflow/utils/session.py", line 97, in wrapper
    return func(*args, session=session, **kwargs)
           ^^^^^^^^^^^^^^^^^^^^^^^^^^^^^^^^^^^^^^
  File "/home/airflow/.local/lib/python3.12/site-packages/airflow/models/taskinstance.py", line 3005, in _run_raw_task
    return _run_raw_task(
           ^^^^^^^^^^^^^^
  File "/home/airflow/.local/lib/python3.12/site-packages/airflow/models/taskinstance.py", line 273, in _run_raw_task
    TaskInstance._execute_task_with_callbacks(
  File "/home/airflow/.local/lib/python3.12/site-packages/airflow/models/taskinstance.py", line 3159, in _execute_task_with_callbacks
    result = self._execute_task(context, task_orig)
             ^^^^^^^^^^^^^^^^^^^^^^^^^^^^^^^^^^^^^^
  File "/home/airflow/.local/lib/python3.12/site-packages/airflow/models/taskinstance.py", line 3183, in _execute_task
    return _execute_task(self, context, task_orig)
           ^^^^^^^^^^^^^^^^^^^^^^^^^^^^^^^^^^^^^^^
  File "/home/airflow/.local/lib/python3.12/site-packages/airflow/models/taskinstance.py", line 767, in _execute_task
    result = _execute_callable(context=context, **execute_callable_kwargs)
             ^^^^^^^^^^^^^^^^^^^^^^^^^^^^^^^^^^^^^^^^^^^^^^^^^^^^^^^^^^^^^
  File "/home/airflow/.local/lib/python3.12/site-packages/airflow/models/taskinstance.py", line 733, in _execute_callable
    return ExecutionCallableRunner(
           ^^^^^^^^^^^^^^^^^^^^^^^^
  File "/home/airflow/.local/lib/python3.12/site-packages/airflow/utils/operator_helpers.py", line 252, in run
    return self.func(*args, **kwargs)
           ^^^^^^^^^^^^^^^^^^^^^^^^^^
  File "/home/airflow/.local/lib/python3.12/site-packages/airflow/models/baseoperator.py", line 422, in wrapper
    return func(self, *args, **kwargs)
           ^^^^^^^^^^^^^^^^^^^^^^^^^^^
  File "/home/airflow/.local/lib/python3.12/site-packages/airflow/operators/python.py", line 238, in execute
    return_value = self.execute_callable()
                   ^^^^^^^^^^^^^^^^^^^^^^^
  File "/home/airflow/.local/lib/python3.12/site-packages/airflow/operators/python.py", line 256, in execute_callable
    return runner.run(*self.op_args, **self.op_kwargs)
           ^^^^^^^^^^^^^^^^^^^^^^^^^^^^^^^^^^^^^^^^^^^
  File "/home/airflow/.local/lib/python3.12/site-packages/airflow/utils/operator_helpers.py", line 252, in run
    return self.func(*args, **kwargs)
           ^^^^^^^^^^^^^^^^^^^^^^^^^^
  File "/opt/airflow/dags/connectBD_to_extract.py", line 10, in run_meltano_script
    subprocess.run(["python", meltano_script_path], check=True)
  File "/usr/local/lib/python3.12/subprocess.py", line 571, in run
    raise CalledProcessError(retcode, process.args,
subprocess.CalledProcessError: Command '['python', '/opt/airflow/meltano_project/transform/extract_data_csv.py']' returned non-zero exit status 2.
[2025-02-09T01:16:24.487+0000] {local_task_job_runner.py:266} INFO - Task exited with return code 1
[2025-02-09T01:16:24.559+0000] {taskinstance.py:3895} INFO - 0 downstream tasks scheduled from follow-on schedule check
[2025-02-09T01:16:24.564+0000] {local_task_job_runner.py:245} INFO - ::endgroup::
