[2025-02-09T15:15:57.270+0000] {local_task_job_runner.py:123} INFO - ::group::Pre task execution logs
[2025-02-09T15:15:57.306+0000] {taskinstance.py:2613} INFO - Dependencies all met for dep_context=non-requeueable deps ti=<TaskInstance: load_csv_to_postgres.load_csv_data scheduled__2025-02-08T00:00:00+00:00 [queued]>
[2025-02-09T15:15:57.322+0000] {taskinstance.py:2613} INFO - Dependencies all met for dep_context=requeueable deps ti=<TaskInstance: load_csv_to_postgres.load_csv_data scheduled__2025-02-08T00:00:00+00:00 [queued]>
[2025-02-09T15:15:57.324+0000] {taskinstance.py:2866} INFO - Starting attempt 1 of 2
[2025-02-09T15:15:57.506+0000] {taskinstance.py:2889} INFO - Executing <Task(BashOperator): load_csv_data> on 2025-02-08 00:00:00+00:00
[2025-02-09T15:15:57.519+0000] {warnings.py:112} WARNING - /home/***/.local/lib/python3.12/site-packages/***/task/task_runner/standard_task_runner.py:70: DeprecationWarning: This process (pid=2066) is multi-threaded, use of fork() may lead to deadlocks in the child.
  pid = os.fork()

[2025-02-09T15:15:57.520+0000] {standard_task_runner.py:104} INFO - Running: ['***', 'tasks', 'run', 'load_csv_to_postgres', 'load_csv_data', 'scheduled__2025-02-08T00:00:00+00:00', '--job-id', '135', '--raw', '--subdir', 'DAGS_FOLDER/Load_CSV_to_Postgres.py', '--cfg-path', '/tmp/tmp1vscebbo']
[2025-02-09T15:15:57.522+0000] {standard_task_runner.py:72} INFO - Started process 2068 to run task
[2025-02-09T15:15:57.523+0000] {standard_task_runner.py:105} INFO - Job 135: Subtask load_csv_data
[2025-02-09T15:15:57.609+0000] {task_command.py:467} INFO - Running <TaskInstance: load_csv_to_postgres.load_csv_data scheduled__2025-02-08T00:00:00+00:00 [running]> on host 8c410daec8d3
[2025-02-09T15:15:57.733+0000] {taskinstance.py:3132} INFO - Exporting env vars: AIRFLOW_CTX_DAG_OWNER='***' AIRFLOW_CTX_DAG_ID='load_csv_to_postgres' AIRFLOW_CTX_TASK_ID='load_csv_data' AIRFLOW_CTX_EXECUTION_DATE='2025-02-08T00:00:00+00:00' AIRFLOW_CTX_TRY_NUMBER='1' AIRFLOW_CTX_DAG_RUN_ID='scheduled__2025-02-08T00:00:00+00:00'
[2025-02-09T15:15:57.735+0000] {logging_mixin.py:190} INFO - Task instance is in running state
[2025-02-09T15:15:57.736+0000] {logging_mixin.py:190} INFO -  Previous state of the Task instance: queued
[2025-02-09T15:15:57.737+0000] {logging_mixin.py:190} INFO - Current task name:load_csv_data state:running start_date:2025-02-09 15:15:57.307769+00:00
[2025-02-09T15:15:57.738+0000] {logging_mixin.py:190} INFO - Dag name:load_csv_to_postgres and current dag run status:running
[2025-02-09T15:15:57.738+0000] {taskinstance.py:731} INFO - ::endgroup::
[2025-02-09T15:15:57.740+0000] {subprocess.py:78} INFO - Tmp dir root location: /tmp
[2025-02-09T15:15:57.741+0000] {subprocess.py:88} INFO - Running command: ['/usr/bin/bash', '-c', 'python /caminho/do/seu/script/load_script.py']
[2025-02-09T15:15:57.772+0000] {subprocess.py:99} INFO - Output:
[2025-02-09T15:15:57.822+0000] {subprocess.py:106} INFO - python: can't open file '/caminho/do/seu/script/load_script.py': [Errno 2] No such file or directory
[2025-02-09T15:15:57.826+0000] {subprocess.py:110} INFO - Command exited with return code 2
[2025-02-09T15:15:57.845+0000] {taskinstance.py:3311} ERROR - Task failed with exception
Traceback (most recent call last):
  File "/home/airflow/.local/lib/python3.12/site-packages/airflow/models/taskinstance.py", line 767, in _execute_task
    result = _execute_callable(context=context, **execute_callable_kwargs)
             ^^^^^^^^^^^^^^^^^^^^^^^^^^^^^^^^^^^^^^^^^^^^^^^^^^^^^^^^^^^^^
  File "/home/airflow/.local/lib/python3.12/site-packages/airflow/models/taskinstance.py", line 733, in _execute_callable
    return ExecutionCallableRunner(
           ^^^^^^^^^^^^^^^^^^^^^^^^
  File "/home/airflow/.local/lib/python3.12/site-packages/airflow/utils/operator_helpers.py", line 252, in run
    return self.func(*args, **kwargs)
           ^^^^^^^^^^^^^^^^^^^^^^^^^^
  File "/home/airflow/.local/lib/python3.12/site-packages/airflow/models/baseoperator.py", line 422, in wrapper
    return func(self, *args, **kwargs)
           ^^^^^^^^^^^^^^^^^^^^^^^^^^^
  File "/home/airflow/.local/lib/python3.12/site-packages/airflow/operators/bash.py", line 276, in execute
    raise AirflowException(
airflow.exceptions.AirflowException: Bash command failed. The command returned a non-zero exit code 2.
[2025-02-09T15:15:57.860+0000] {logging_mixin.py:190} INFO - Task instance in failure state
[2025-02-09T15:15:57.861+0000] {logging_mixin.py:190} INFO - Task start:2025-02-09 15:15:57.307769+00:00 end:2025-02-09 15:15:57.859127+00:00 duration:0.551358
[2025-02-09T15:15:57.862+0000] {logging_mixin.py:190} INFO - Task:<Task(BashOperator): load_csv_data> dag:<DAG: load_csv_to_postgres> dagrun:<DagRun load_csv_to_postgres @ 2025-02-08 00:00:00+00:00: scheduled__2025-02-08T00:00:00+00:00, state:running, queued_at: 2025-02-09 15:15:48.766028+00:00. externally triggered: False>
[2025-02-09T15:15:57.863+0000] {logging_mixin.py:190} INFO - Failure caused by Bash command failed. The command returned a non-zero exit code 2.
[2025-02-09T15:15:57.864+0000] {taskinstance.py:1225} INFO - Marking task as UP_FOR_RETRY. dag_id=load_csv_to_postgres, task_id=load_csv_data, run_id=scheduled__2025-02-08T00:00:00+00:00, execution_date=20250208T000000, start_date=20250209T151557, end_date=20250209T151557
[2025-02-09T15:15:57.891+0000] {taskinstance.py:340} INFO - ::group::Post task execution logs
[2025-02-09T15:15:57.893+0000] {standard_task_runner.py:124} ERROR - Failed to execute job 135 for task load_csv_data (Bash command failed. The command returned a non-zero exit code 2.; 2068)
Traceback (most recent call last):
  File "/home/airflow/.local/lib/python3.12/site-packages/airflow/task/task_runner/standard_task_runner.py", line 117, in _start_by_fork
    ret = args.func(args, dag=self.dag)
          ^^^^^^^^^^^^^^^^^^^^^^^^^^^^^
  File "/home/airflow/.local/lib/python3.12/site-packages/airflow/cli/cli_config.py", line 49, in command
    return func(*args, **kwargs)
           ^^^^^^^^^^^^^^^^^^^^^
  File "/home/airflow/.local/lib/python3.12/site-packages/airflow/utils/cli.py", line 116, in wrapper
    return f(*args, **kwargs)
           ^^^^^^^^^^^^^^^^^^
  File "/home/airflow/.local/lib/python3.12/site-packages/airflow/cli/commands/task_command.py", line 483, in task_run
    task_return_code = _run_task_by_selected_method(args, _dag, ti)
                       ^^^^^^^^^^^^^^^^^^^^^^^^^^^^^^^^^^^^^^^^^^^^
  File "/home/airflow/.local/lib/python3.12/site-packages/airflow/cli/commands/task_command.py", line 256, in _run_task_by_selected_method
    return _run_raw_task(args, ti)
           ^^^^^^^^^^^^^^^^^^^^^^^
  File "/home/airflow/.local/lib/python3.12/site-packages/airflow/cli/commands/task_command.py", line 341, in _run_raw_task
    return ti._run_raw_task(
           ^^^^^^^^^^^^^^^^^
  File "/home/airflow/.local/lib/python3.12/site-packages/airflow/utils/session.py", line 97, in wrapper
    return func(*args, session=session, **kwargs)
           ^^^^^^^^^^^^^^^^^^^^^^^^^^^^^^^^^^^^^^
  File "/home/airflow/.local/lib/python3.12/site-packages/airflow/models/taskinstance.py", line 3005, in _run_raw_task
    return _run_raw_task(
           ^^^^^^^^^^^^^^
  File "/home/airflow/.local/lib/python3.12/site-packages/airflow/models/taskinstance.py", line 273, in _run_raw_task
    TaskInstance._execute_task_with_callbacks(
  File "/home/airflow/.local/lib/python3.12/site-packages/airflow/models/taskinstance.py", line 3159, in _execute_task_with_callbacks
    result = self._execute_task(context, task_orig)
             ^^^^^^^^^^^^^^^^^^^^^^^^^^^^^^^^^^^^^^
  File "/home/airflow/.local/lib/python3.12/site-packages/airflow/models/taskinstance.py", line 3183, in _execute_task
    return _execute_task(self, context, task_orig)
           ^^^^^^^^^^^^^^^^^^^^^^^^^^^^^^^^^^^^^^^
  File "/home/airflow/.local/lib/python3.12/site-packages/airflow/models/taskinstance.py", line 767, in _execute_task
    result = _execute_callable(context=context, **execute_callable_kwargs)
             ^^^^^^^^^^^^^^^^^^^^^^^^^^^^^^^^^^^^^^^^^^^^^^^^^^^^^^^^^^^^^
  File "/home/airflow/.local/lib/python3.12/site-packages/airflow/models/taskinstance.py", line 733, in _execute_callable
    return ExecutionCallableRunner(
           ^^^^^^^^^^^^^^^^^^^^^^^^
  File "/home/airflow/.local/lib/python3.12/site-packages/airflow/utils/operator_helpers.py", line 252, in run
    return self.func(*args, **kwargs)
           ^^^^^^^^^^^^^^^^^^^^^^^^^^
  File "/home/airflow/.local/lib/python3.12/site-packages/airflow/models/baseoperator.py", line 422, in wrapper
    return func(self, *args, **kwargs)
           ^^^^^^^^^^^^^^^^^^^^^^^^^^^
  File "/home/airflow/.local/lib/python3.12/site-packages/airflow/operators/bash.py", line 276, in execute
    raise AirflowException(
airflow.exceptions.AirflowException: Bash command failed. The command returned a non-zero exit code 2.
[2025-02-09T15:15:57.943+0000] {local_task_job_runner.py:266} INFO - Task exited with return code 1
[2025-02-09T15:15:57.982+0000] {taskinstance.py:3895} INFO - 0 downstream tasks scheduled from follow-on schedule check
[2025-02-09T15:15:57.985+0000] {local_task_job_runner.py:245} INFO - ::endgroup::
