[2025-02-09T18:44:25.298+0000] {local_task_job_runner.py:123} INFO - ::group::Pre task execution logs
[2025-02-09T18:44:25.318+0000] {taskinstance.py:2613} INFO - Dependencies all met for dep_context=non-requeueable deps ti=<TaskInstance: extract_postgres_and_csv_data.run_load_data_script manual__2025-02-09T18:39:10.439799+00:00 [queued]>
[2025-02-09T18:44:25.329+0000] {taskinstance.py:2613} INFO - Dependencies all met for dep_context=requeueable deps ti=<TaskInstance: extract_postgres_and_csv_data.run_load_data_script manual__2025-02-09T18:39:10.439799+00:00 [queued]>
[2025-02-09T18:44:25.331+0000] {taskinstance.py:2866} INFO - Starting attempt 2 of 2
[2025-02-09T18:44:25.556+0000] {taskinstance.py:2889} INFO - Executing <Task(BashOperator): run_load_data_script> on 2025-02-09 18:39:10.439799+00:00
[2025-02-09T18:44:25.569+0000] {warnings.py:112} WARNING - /home/***/.local/lib/python3.12/site-packages/***/task/task_runner/standard_task_runner.py:70: DeprecationWarning: This process (pid=575) is multi-threaded, use of fork() may lead to deadlocks in the child.
  pid = os.fork()

[2025-02-09T18:44:25.572+0000] {standard_task_runner.py:72} INFO - Started process 577 to run task
[2025-02-09T18:44:25.572+0000] {standard_task_runner.py:104} INFO - Running: ['***', 'tasks', 'run', 'extract_postgres_and_csv_data', 'run_load_data_script', 'manual__2025-02-09T18:39:10.439799+00:00', '--job-id', '275', '--raw', '--subdir', 'DAGS_FOLDER/extract_postgres_and_csv_data.py', '--cfg-path', '/tmp/tmp9tv6kwsz']
[2025-02-09T18:44:25.574+0000] {standard_task_runner.py:105} INFO - Job 275: Subtask run_load_data_script
[2025-02-09T18:44:25.656+0000] {task_command.py:467} INFO - Running <TaskInstance: extract_postgres_and_csv_data.run_load_data_script manual__2025-02-09T18:39:10.439799+00:00 [running]> on host 58bc83bc12fd
[2025-02-09T18:44:25.798+0000] {taskinstance.py:3132} INFO - Exporting env vars: AIRFLOW_CTX_DAG_OWNER='***' AIRFLOW_CTX_DAG_ID='extract_postgres_and_csv_data' AIRFLOW_CTX_TASK_ID='run_load_data_script' AIRFLOW_CTX_EXECUTION_DATE='2025-02-09T18:39:10.439799+00:00' AIRFLOW_CTX_TRY_NUMBER='2' AIRFLOW_CTX_DAG_RUN_ID='manual__2025-02-09T18:39:10.439799+00:00'
[2025-02-09T18:44:25.799+0000] {logging_mixin.py:190} INFO - Task instance is in running state
[2025-02-09T18:44:25.800+0000] {logging_mixin.py:190} INFO -  Previous state of the Task instance: queued
[2025-02-09T18:44:25.801+0000] {logging_mixin.py:190} INFO - Current task name:run_load_data_script state:running start_date:2025-02-09 18:44:25.319804+00:00
[2025-02-09T18:44:25.801+0000] {logging_mixin.py:190} INFO - Dag name:extract_postgres_and_csv_data and current dag run status:running
[2025-02-09T18:44:25.802+0000] {taskinstance.py:731} INFO - ::endgroup::
[2025-02-09T18:44:25.804+0000] {subprocess.py:78} INFO - Tmp dir root location: /tmp
[2025-02-09T18:44:25.808+0000] {subprocess.py:88} INFO - Running command: ['/usr/bin/bash', '-c', 'python /opt/***/meltano/meltano_project/load/load_data_csv_for_db.py']
[2025-02-09T18:44:25.826+0000] {subprocess.py:99} INFO - Output:
[2025-02-09T18:44:27.615+0000] {subprocess.py:106} INFO - Traceback (most recent call last):
[2025-02-09T18:44:27.615+0000] {subprocess.py:106} INFO -   File "/opt/***/meltano/meltano_project/load/load_data_csv_for_db.py", line 7, in <module>
[2025-02-09T18:44:27.621+0000] {subprocess.py:106} INFO -     import openpyxl
[2025-02-09T18:44:27.622+0000] {subprocess.py:106} INFO - ModuleNotFoundError: No module named 'openpyxl'
[2025-02-09T18:44:27.623+0000] {subprocess.py:106} INFO - 
[2025-02-09T18:44:27.623+0000] {subprocess.py:106} INFO - During handling of the above exception, another exception occurred:
[2025-02-09T18:44:27.624+0000] {subprocess.py:106} INFO - 
[2025-02-09T18:44:27.625+0000] {subprocess.py:106} INFO - Traceback (most recent call last):
[2025-02-09T18:44:27.625+0000] {subprocess.py:106} INFO -   File "/opt/***/meltano/meltano_project/load/load_data_csv_for_db.py", line 9, in <module>
[2025-02-09T18:44:27.626+0000] {subprocess.py:106} INFO -     raise ImportError("O módulo 'openpyxl' não está instalado. Instale-o com 'pip install openpyxl'.")
[2025-02-09T18:44:27.627+0000] {subprocess.py:106} INFO - ImportError: O módulo 'openpyxl' não está instalado. Instale-o com 'pip install openpyxl'.
[2025-02-09T18:44:27.752+0000] {subprocess.py:110} INFO - Command exited with return code 1
[2025-02-09T18:44:27.768+0000] {taskinstance.py:3311} ERROR - Task failed with exception
Traceback (most recent call last):
  File "/home/airflow/.local/lib/python3.12/site-packages/airflow/models/taskinstance.py", line 767, in _execute_task
    result = _execute_callable(context=context, **execute_callable_kwargs)
             ^^^^^^^^^^^^^^^^^^^^^^^^^^^^^^^^^^^^^^^^^^^^^^^^^^^^^^^^^^^^^
  File "/home/airflow/.local/lib/python3.12/site-packages/airflow/models/taskinstance.py", line 733, in _execute_callable
    return ExecutionCallableRunner(
           ^^^^^^^^^^^^^^^^^^^^^^^^
  File "/home/airflow/.local/lib/python3.12/site-packages/airflow/utils/operator_helpers.py", line 252, in run
    return self.func(*args, **kwargs)
           ^^^^^^^^^^^^^^^^^^^^^^^^^^
  File "/home/airflow/.local/lib/python3.12/site-packages/airflow/models/baseoperator.py", line 422, in wrapper
    return func(self, *args, **kwargs)
           ^^^^^^^^^^^^^^^^^^^^^^^^^^^
  File "/home/airflow/.local/lib/python3.12/site-packages/airflow/operators/bash.py", line 276, in execute
    raise AirflowException(
airflow.exceptions.AirflowException: Bash command failed. The command returned a non-zero exit code 1.
[2025-02-09T18:44:27.774+0000] {logging_mixin.py:190} INFO - Task instance in failure state
[2025-02-09T18:44:27.775+0000] {logging_mixin.py:190} INFO - Task start:2025-02-09 18:44:25.319804+00:00 end:2025-02-09 18:44:27.773352+00:00 duration:2.453548
[2025-02-09T18:44:27.776+0000] {logging_mixin.py:190} INFO - Task:<Task(BashOperator): run_load_data_script> dag:<DAG: extract_postgres_and_csv_data> dagrun:<DagRun extract_postgres_and_csv_data @ 2025-02-09 18:39:10.439799+00:00: manual__2025-02-09T18:39:10.439799+00:00, state:running, queued_at: 2025-02-09 18:39:10.454504+00:00. externally triggered: True>
[2025-02-09T18:44:27.776+0000] {logging_mixin.py:190} INFO - Failure caused by Bash command failed. The command returned a non-zero exit code 1.
[2025-02-09T18:44:27.777+0000] {taskinstance.py:1225} INFO - Marking task as FAILED. dag_id=extract_postgres_and_csv_data, task_id=run_load_data_script, run_id=manual__2025-02-09T18:39:10.439799+00:00, execution_date=20250209T183910, start_date=20250209T184425, end_date=20250209T184427
[2025-02-09T18:44:27.801+0000] {taskinstance.py:340} INFO - ::group::Post task execution logs
[2025-02-09T18:44:27.802+0000] {standard_task_runner.py:124} ERROR - Failed to execute job 275 for task run_load_data_script (Bash command failed. The command returned a non-zero exit code 1.; 577)
Traceback (most recent call last):
  File "/home/airflow/.local/lib/python3.12/site-packages/airflow/task/task_runner/standard_task_runner.py", line 117, in _start_by_fork
    ret = args.func(args, dag=self.dag)
          ^^^^^^^^^^^^^^^^^^^^^^^^^^^^^
  File "/home/airflow/.local/lib/python3.12/site-packages/airflow/cli/cli_config.py", line 49, in command
    return func(*args, **kwargs)
           ^^^^^^^^^^^^^^^^^^^^^
  File "/home/airflow/.local/lib/python3.12/site-packages/airflow/utils/cli.py", line 116, in wrapper
    return f(*args, **kwargs)
           ^^^^^^^^^^^^^^^^^^
  File "/home/airflow/.local/lib/python3.12/site-packages/airflow/cli/commands/task_command.py", line 483, in task_run
    task_return_code = _run_task_by_selected_method(args, _dag, ti)
                       ^^^^^^^^^^^^^^^^^^^^^^^^^^^^^^^^^^^^^^^^^^^^
  File "/home/airflow/.local/lib/python3.12/site-packages/airflow/cli/commands/task_command.py", line 256, in _run_task_by_selected_method
    return _run_raw_task(args, ti)
           ^^^^^^^^^^^^^^^^^^^^^^^
  File "/home/airflow/.local/lib/python3.12/site-packages/airflow/cli/commands/task_command.py", line 341, in _run_raw_task
    return ti._run_raw_task(
           ^^^^^^^^^^^^^^^^^
  File "/home/airflow/.local/lib/python3.12/site-packages/airflow/utils/session.py", line 97, in wrapper
    return func(*args, session=session, **kwargs)
           ^^^^^^^^^^^^^^^^^^^^^^^^^^^^^^^^^^^^^^
  File "/home/airflow/.local/lib/python3.12/site-packages/airflow/models/taskinstance.py", line 3005, in _run_raw_task
    return _run_raw_task(
           ^^^^^^^^^^^^^^
  File "/home/airflow/.local/lib/python3.12/site-packages/airflow/models/taskinstance.py", line 273, in _run_raw_task
    TaskInstance._execute_task_with_callbacks(
  File "/home/airflow/.local/lib/python3.12/site-packages/airflow/models/taskinstance.py", line 3159, in _execute_task_with_callbacks
    result = self._execute_task(context, task_orig)
             ^^^^^^^^^^^^^^^^^^^^^^^^^^^^^^^^^^^^^^
  File "/home/airflow/.local/lib/python3.12/site-packages/airflow/models/taskinstance.py", line 3183, in _execute_task
    return _execute_task(self, context, task_orig)
           ^^^^^^^^^^^^^^^^^^^^^^^^^^^^^^^^^^^^^^^
  File "/home/airflow/.local/lib/python3.12/site-packages/airflow/models/taskinstance.py", line 767, in _execute_task
    result = _execute_callable(context=context, **execute_callable_kwargs)
             ^^^^^^^^^^^^^^^^^^^^^^^^^^^^^^^^^^^^^^^^^^^^^^^^^^^^^^^^^^^^^
  File "/home/airflow/.local/lib/python3.12/site-packages/airflow/models/taskinstance.py", line 733, in _execute_callable
    return ExecutionCallableRunner(
           ^^^^^^^^^^^^^^^^^^^^^^^^
  File "/home/airflow/.local/lib/python3.12/site-packages/airflow/utils/operator_helpers.py", line 252, in run
    return self.func(*args, **kwargs)
           ^^^^^^^^^^^^^^^^^^^^^^^^^^
  File "/home/airflow/.local/lib/python3.12/site-packages/airflow/models/baseoperator.py", line 422, in wrapper
    return func(self, *args, **kwargs)
           ^^^^^^^^^^^^^^^^^^^^^^^^^^^
  File "/home/airflow/.local/lib/python3.12/site-packages/airflow/operators/bash.py", line 276, in execute
    raise AirflowException(
airflow.exceptions.AirflowException: Bash command failed. The command returned a non-zero exit code 1.
[2025-02-09T18:44:27.857+0000] {local_task_job_runner.py:266} INFO - Task exited with return code 1
[2025-02-09T18:44:27.879+0000] {taskinstance.py:3895} INFO - 0 downstream tasks scheduled from follow-on schedule check
[2025-02-09T18:44:27.882+0000] {local_task_job_runner.py:245} INFO - ::endgroup::
