[2025-02-09T09:57:30.181+0000] {local_task_job_runner.py:123} INFO - ::group::Pre task execution logs
[2025-02-09T09:57:30.203+0000] {taskinstance.py:2613} INFO - Dependencies all met for dep_context=non-requeueable deps ti=<TaskInstance: Extract_DB_data.run_meltano_script_db manual__2025-02-09T09:55:21.913198+00:00 [queued]>
[2025-02-09T09:57:30.213+0000] {taskinstance.py:2613} INFO - Dependencies all met for dep_context=requeueable deps ti=<TaskInstance: Extract_DB_data.run_meltano_script_db manual__2025-02-09T09:55:21.913198+00:00 [queued]>
[2025-02-09T09:57:30.214+0000] {taskinstance.py:2866} INFO - Starting attempt 2 of 3
[2025-02-09T09:57:30.391+0000] {taskinstance.py:2889} INFO - Executing <Task(PythonOperator): run_meltano_script_db> on 2025-02-09 09:55:21.913198+00:00
[2025-02-09T09:57:30.401+0000] {warnings.py:112} WARNING - /home/***/.local/lib/python3.12/site-packages/***/task/task_runner/standard_task_runner.py:70: DeprecationWarning: This process (pid=389) is multi-threaded, use of fork() may lead to deadlocks in the child.
  pid = os.fork()

[2025-02-09T09:57:30.404+0000] {standard_task_runner.py:72} INFO - Started process 391 to run task
[2025-02-09T09:57:30.404+0000] {standard_task_runner.py:104} INFO - Running: ['***', 'tasks', 'run', 'Extract_DB_data', 'run_meltano_script_db', 'manual__2025-02-09T09:55:21.913198+00:00', '--job-id', '53', '--raw', '--subdir', 'DAGS_FOLDER/Extract_DB_data.py', '--cfg-path', '/tmp/tmpqdfpq4oi']
[2025-02-09T09:57:30.406+0000] {standard_task_runner.py:105} INFO - Job 53: Subtask run_meltano_script_db
[2025-02-09T09:57:30.470+0000] {task_command.py:467} INFO - Running <TaskInstance: Extract_DB_data.run_meltano_script_db manual__2025-02-09T09:55:21.913198+00:00 [running]> on host 82ce0ea42bb9
[2025-02-09T09:57:30.591+0000] {taskinstance.py:3132} INFO - Exporting env vars: AIRFLOW_CTX_DAG_OWNER='***' AIRFLOW_CTX_DAG_ID='Extract_DB_data' AIRFLOW_CTX_TASK_ID='run_meltano_script_db' AIRFLOW_CTX_EXECUTION_DATE='2025-02-09T09:55:21.913198+00:00' AIRFLOW_CTX_TRY_NUMBER='2' AIRFLOW_CTX_DAG_RUN_ID='manual__2025-02-09T09:55:21.913198+00:00'
[2025-02-09T09:57:30.592+0000] {logging_mixin.py:190} INFO - Task instance is in running state
[2025-02-09T09:57:30.593+0000] {logging_mixin.py:190} INFO -  Previous state of the Task instance: queued
[2025-02-09T09:57:30.594+0000] {logging_mixin.py:190} INFO - Current task name:run_meltano_script_db state:running start_date:2025-02-09 09:57:30.204033+00:00
[2025-02-09T09:57:30.594+0000] {logging_mixin.py:190} INFO - Dag name:Extract_DB_data and current dag run status:running
[2025-02-09T09:57:30.595+0000] {taskinstance.py:731} INFO - ::endgroup::
[2025-02-09T10:01:01.905+0000] {local_task_job_runner.py:346} WARNING - State of this instance has been externally set to restarting. Terminating instance.
[2025-02-09T10:01:01.906+0000] {local_task_job_runner.py:245} INFO - ::endgroup::
[2025-02-09T10:01:01.908+0000] {process_utils.py:132} INFO - Sending 15 to group 391. PIDs of all processes in the group: [393, 391]
[2025-02-09T10:01:01.909+0000] {process_utils.py:87} INFO - Sending the signal 15 to group 391
[2025-02-09T10:01:01.910+0000] {taskinstance.py:3093} ERROR - Received SIGTERM. Terminating subprocesses.
[2025-02-09T10:01:01.912+0000] {process_utils.py:80} INFO - Process psutil.Process(pid=393, status='terminated', started='09:57:30') (393) terminated with exit code None
[2025-02-09T10:01:01.928+0000] {taskinstance.py:3311} ERROR - Task failed with exception
Traceback (most recent call last):
  File "/home/airflow/.local/lib/python3.12/site-packages/airflow/models/taskinstance.py", line 767, in _execute_task
    result = _execute_callable(context=context, **execute_callable_kwargs)
             ^^^^^^^^^^^^^^^^^^^^^^^^^^^^^^^^^^^^^^^^^^^^^^^^^^^^^^^^^^^^^
  File "/home/airflow/.local/lib/python3.12/site-packages/airflow/models/taskinstance.py", line 733, in _execute_callable
    return ExecutionCallableRunner(
           ^^^^^^^^^^^^^^^^^^^^^^^^
  File "/home/airflow/.local/lib/python3.12/site-packages/airflow/utils/operator_helpers.py", line 252, in run
    return self.func(*args, **kwargs)
           ^^^^^^^^^^^^^^^^^^^^^^^^^^
  File "/home/airflow/.local/lib/python3.12/site-packages/airflow/models/baseoperator.py", line 422, in wrapper
    return func(self, *args, **kwargs)
           ^^^^^^^^^^^^^^^^^^^^^^^^^^^
  File "/home/airflow/.local/lib/python3.12/site-packages/airflow/operators/python.py", line 238, in execute
    return_value = self.execute_callable()
                   ^^^^^^^^^^^^^^^^^^^^^^^
  File "/home/airflow/.local/lib/python3.12/site-packages/airflow/operators/python.py", line 256, in execute_callable
    return runner.run(*self.op_args, **self.op_kwargs)
           ^^^^^^^^^^^^^^^^^^^^^^^^^^^^^^^^^^^^^^^^^^^
  File "/home/airflow/.local/lib/python3.12/site-packages/airflow/utils/operator_helpers.py", line 252, in run
    return self.func(*args, **kwargs)
           ^^^^^^^^^^^^^^^^^^^^^^^^^^
  File "/opt/airflow/dags/Extract_DB_data.py", line 10, in run_meltano_script
    subprocess.run(["python", script_path], check=True)
  File "/usr/local/lib/python3.12/subprocess.py", line 550, in run
    stdout, stderr = process.communicate(input, timeout=timeout)
                     ^^^^^^^^^^^^^^^^^^^^^^^^^^^^^^^^^^^^^^^^^^^
  File "/usr/local/lib/python3.12/subprocess.py", line 1201, in communicate
    self.wait()
  File "/usr/local/lib/python3.12/subprocess.py", line 1264, in wait
    return self._wait(timeout=timeout)
           ^^^^^^^^^^^^^^^^^^^^^^^^^^^
  File "/usr/local/lib/python3.12/subprocess.py", line 2053, in _wait
    (pid, sts) = self._try_wait(0)
                 ^^^^^^^^^^^^^^^^^
  File "/usr/local/lib/python3.12/subprocess.py", line 2011, in _try_wait
    (pid, sts) = os.waitpid(self.pid, wait_flags)
                 ^^^^^^^^^^^^^^^^^^^^^^^^^^^^^^^^
  File "/home/airflow/.local/lib/python3.12/site-packages/airflow/models/taskinstance.py", line 3095, in signal_handler
    raise AirflowTaskTerminated("Task received SIGTERM signal")
airflow.exceptions.AirflowTaskTerminated: Task received SIGTERM signal
[2025-02-09T10:01:01.942+0000] {logging_mixin.py:190} INFO - Task instance in failure state
[2025-02-09T10:01:01.942+0000] {logging_mixin.py:190} INFO - Task start:2025-02-09 09:57:30.204033+00:00 end:2025-02-09 10:01:01.940747+00:00 duration:211.736714
[2025-02-09T10:01:01.944+0000] {logging_mixin.py:190} INFO - Task:<Task(PythonOperator): run_meltano_script_db> dag:<DAG: Extract_DB_data> dagrun:<DagRun Extract_DB_data @ 2025-02-09 09:55:21.913198+00:00: manual__2025-02-09T09:55:21.913198+00:00, state:running, queued_at: 2025-02-09 09:55:21.928710+00:00. externally triggered: True>
[2025-02-09T10:01:01.944+0000] {logging_mixin.py:190} INFO - Failure caused by Task received SIGTERM signal
[2025-02-09T10:01:01.945+0000] {taskinstance.py:1225} INFO - Marking task as UP_FOR_RETRY. dag_id=Extract_DB_data, task_id=run_meltano_script_db, run_id=manual__2025-02-09T09:55:21.913198+00:00, execution_date=20250209T095521, start_date=20250209T095730, end_date=20250209T100101
[2025-02-09T10:01:01.969+0000] {taskinstance.py:340} INFO - ::group::Post task execution logs
[2025-02-09T10:01:02.007+0000] {process_utils.py:80} INFO - Process psutil.Process(pid=391, status='terminated', exitcode=2, started='09:57:30') (391) terminated with exit code 2
