[2025-02-09T18:36:20.473+0000] {local_task_job_runner.py:123} INFO - ::group::Pre task execution logs
[2025-02-09T18:36:20.499+0000] {taskinstance.py:2613} INFO - Dependencies all met for dep_context=non-requeueable deps ti=<TaskInstance: extract_postgres_and_csv_data.run_load_data_script manual__2025-02-09T18:31:03.612016+00:00 [queued]>
[2025-02-09T18:36:20.512+0000] {taskinstance.py:2613} INFO - Dependencies all met for dep_context=requeueable deps ti=<TaskInstance: extract_postgres_and_csv_data.run_load_data_script manual__2025-02-09T18:31:03.612016+00:00 [queued]>
[2025-02-09T18:36:20.513+0000] {taskinstance.py:2866} INFO - Starting attempt 2 of 2
[2025-02-09T18:36:20.699+0000] {taskinstance.py:2889} INFO - Executing <Task(BashOperator): run_load_data_script> on 2025-02-09 18:31:03.612016+00:00
[2025-02-09T18:36:20.711+0000] {warnings.py:112} WARNING - /home/***/.local/lib/python3.12/site-packages/***/task/task_runner/standard_task_runner.py:70: DeprecationWarning: This process (pid=391) is multi-threaded, use of fork() may lead to deadlocks in the child.
  pid = os.fork()

[2025-02-09T18:36:20.714+0000] {standard_task_runner.py:72} INFO - Started process 393 to run task
[2025-02-09T18:36:20.714+0000] {standard_task_runner.py:104} INFO - Running: ['***', 'tasks', 'run', 'extract_postgres_and_csv_data', 'run_load_data_script', 'manual__2025-02-09T18:31:03.612016+00:00', '--job-id', '261', '--raw', '--subdir', 'DAGS_FOLDER/extract_postgres_and_csv_data.py', '--cfg-path', '/tmp/tmppccgfvrv']
[2025-02-09T18:36:20.716+0000] {standard_task_runner.py:105} INFO - Job 261: Subtask run_load_data_script
[2025-02-09T18:36:20.786+0000] {task_command.py:467} INFO - Running <TaskInstance: extract_postgres_and_csv_data.run_load_data_script manual__2025-02-09T18:31:03.612016+00:00 [running]> on host 58bc83bc12fd
[2025-02-09T18:36:20.923+0000] {taskinstance.py:3132} INFO - Exporting env vars: AIRFLOW_CTX_DAG_OWNER='***' AIRFLOW_CTX_DAG_ID='extract_postgres_and_csv_data' AIRFLOW_CTX_TASK_ID='run_load_data_script' AIRFLOW_CTX_EXECUTION_DATE='2025-02-09T18:31:03.612016+00:00' AIRFLOW_CTX_TRY_NUMBER='2' AIRFLOW_CTX_DAG_RUN_ID='manual__2025-02-09T18:31:03.612016+00:00'
[2025-02-09T18:36:20.925+0000] {logging_mixin.py:190} INFO - Task instance is in running state
[2025-02-09T18:36:20.926+0000] {logging_mixin.py:190} INFO -  Previous state of the Task instance: queued
[2025-02-09T18:36:20.927+0000] {logging_mixin.py:190} INFO - Current task name:run_load_data_script state:running start_date:2025-02-09 18:36:20.500263+00:00
[2025-02-09T18:36:20.928+0000] {logging_mixin.py:190} INFO - Dag name:extract_postgres_and_csv_data and current dag run status:running
[2025-02-09T18:36:20.929+0000] {taskinstance.py:731} INFO - ::endgroup::
[2025-02-09T18:36:20.930+0000] {subprocess.py:78} INFO - Tmp dir root location: /tmp
[2025-02-09T18:36:20.931+0000] {subprocess.py:88} INFO - Running command: ['/usr/bin/bash', '-c', '/usr/bin/python3 /opt/***/meltano/meltano_project/load/load_data_csv_for_db.py']
[2025-02-09T18:36:20.950+0000] {subprocess.py:99} INFO - Output:
[2025-02-09T18:36:21.006+0000] {subprocess.py:106} INFO - Traceback (most recent call last):
[2025-02-09T18:36:21.007+0000] {subprocess.py:106} INFO -   File "/opt/***/meltano/meltano_project/load/load_data_csv_for_db.py", line 2, in <module>
[2025-02-09T18:36:21.012+0000] {subprocess.py:106} INFO -     import pandas as pd
[2025-02-09T18:36:21.013+0000] {subprocess.py:106} INFO - ModuleNotFoundError: No module named 'pandas'
[2025-02-09T18:36:21.015+0000] {subprocess.py:110} INFO - Command exited with return code 1
[2025-02-09T18:36:21.033+0000] {taskinstance.py:3311} ERROR - Task failed with exception
Traceback (most recent call last):
  File "/home/airflow/.local/lib/python3.12/site-packages/airflow/models/taskinstance.py", line 767, in _execute_task
    result = _execute_callable(context=context, **execute_callable_kwargs)
             ^^^^^^^^^^^^^^^^^^^^^^^^^^^^^^^^^^^^^^^^^^^^^^^^^^^^^^^^^^^^^
  File "/home/airflow/.local/lib/python3.12/site-packages/airflow/models/taskinstance.py", line 733, in _execute_callable
    return ExecutionCallableRunner(
           ^^^^^^^^^^^^^^^^^^^^^^^^
  File "/home/airflow/.local/lib/python3.12/site-packages/airflow/utils/operator_helpers.py", line 252, in run
    return self.func(*args, **kwargs)
           ^^^^^^^^^^^^^^^^^^^^^^^^^^
  File "/home/airflow/.local/lib/python3.12/site-packages/airflow/models/baseoperator.py", line 422, in wrapper
    return func(self, *args, **kwargs)
           ^^^^^^^^^^^^^^^^^^^^^^^^^^^
  File "/home/airflow/.local/lib/python3.12/site-packages/airflow/operators/bash.py", line 276, in execute
    raise AirflowException(
airflow.exceptions.AirflowException: Bash command failed. The command returned a non-zero exit code 1.
[2025-02-09T18:36:21.043+0000] {logging_mixin.py:190} INFO - Task instance in failure state
[2025-02-09T18:36:21.044+0000] {logging_mixin.py:190} INFO - Task start:2025-02-09 18:36:20.500263+00:00 end:2025-02-09 18:36:21.042209+00:00 duration:0.541946
[2025-02-09T18:36:21.045+0000] {logging_mixin.py:190} INFO - Task:<Task(BashOperator): run_load_data_script> dag:<DAG: extract_postgres_and_csv_data> dagrun:<DagRun extract_postgres_and_csv_data @ 2025-02-09 18:31:03.612016+00:00: manual__2025-02-09T18:31:03.612016+00:00, state:running, queued_at: 2025-02-09 18:31:03.629627+00:00. externally triggered: True>
[2025-02-09T18:36:21.046+0000] {logging_mixin.py:190} INFO - Failure caused by Bash command failed. The command returned a non-zero exit code 1.
[2025-02-09T18:36:21.047+0000] {taskinstance.py:1225} INFO - Marking task as FAILED. dag_id=extract_postgres_and_csv_data, task_id=run_load_data_script, run_id=manual__2025-02-09T18:31:03.612016+00:00, execution_date=20250209T183103, start_date=20250209T183620, end_date=20250209T183621
[2025-02-09T18:36:21.071+0000] {taskinstance.py:340} INFO - ::group::Post task execution logs
[2025-02-09T18:36:21.072+0000] {standard_task_runner.py:124} ERROR - Failed to execute job 261 for task run_load_data_script (Bash command failed. The command returned a non-zero exit code 1.; 393)
Traceback (most recent call last):
  File "/home/airflow/.local/lib/python3.12/site-packages/airflow/task/task_runner/standard_task_runner.py", line 117, in _start_by_fork
    ret = args.func(args, dag=self.dag)
          ^^^^^^^^^^^^^^^^^^^^^^^^^^^^^
  File "/home/airflow/.local/lib/python3.12/site-packages/airflow/cli/cli_config.py", line 49, in command
    return func(*args, **kwargs)
           ^^^^^^^^^^^^^^^^^^^^^
  File "/home/airflow/.local/lib/python3.12/site-packages/airflow/utils/cli.py", line 116, in wrapper
    return f(*args, **kwargs)
           ^^^^^^^^^^^^^^^^^^
  File "/home/airflow/.local/lib/python3.12/site-packages/airflow/cli/commands/task_command.py", line 483, in task_run
    task_return_code = _run_task_by_selected_method(args, _dag, ti)
                       ^^^^^^^^^^^^^^^^^^^^^^^^^^^^^^^^^^^^^^^^^^^^
  File "/home/airflow/.local/lib/python3.12/site-packages/airflow/cli/commands/task_command.py", line 256, in _run_task_by_selected_method
    return _run_raw_task(args, ti)
           ^^^^^^^^^^^^^^^^^^^^^^^
  File "/home/airflow/.local/lib/python3.12/site-packages/airflow/cli/commands/task_command.py", line 341, in _run_raw_task
    return ti._run_raw_task(
           ^^^^^^^^^^^^^^^^^
  File "/home/airflow/.local/lib/python3.12/site-packages/airflow/utils/session.py", line 97, in wrapper
    return func(*args, session=session, **kwargs)
           ^^^^^^^^^^^^^^^^^^^^^^^^^^^^^^^^^^^^^^
  File "/home/airflow/.local/lib/python3.12/site-packages/airflow/models/taskinstance.py", line 3005, in _run_raw_task
    return _run_raw_task(
           ^^^^^^^^^^^^^^
  File "/home/airflow/.local/lib/python3.12/site-packages/airflow/models/taskinstance.py", line 273, in _run_raw_task
    TaskInstance._execute_task_with_callbacks(
  File "/home/airflow/.local/lib/python3.12/site-packages/airflow/models/taskinstance.py", line 3159, in _execute_task_with_callbacks
    result = self._execute_task(context, task_orig)
             ^^^^^^^^^^^^^^^^^^^^^^^^^^^^^^^^^^^^^^
  File "/home/airflow/.local/lib/python3.12/site-packages/airflow/models/taskinstance.py", line 3183, in _execute_task
    return _execute_task(self, context, task_orig)
           ^^^^^^^^^^^^^^^^^^^^^^^^^^^^^^^^^^^^^^^
  File "/home/airflow/.local/lib/python3.12/site-packages/airflow/models/taskinstance.py", line 767, in _execute_task
    result = _execute_callable(context=context, **execute_callable_kwargs)
             ^^^^^^^^^^^^^^^^^^^^^^^^^^^^^^^^^^^^^^^^^^^^^^^^^^^^^^^^^^^^^
  File "/home/airflow/.local/lib/python3.12/site-packages/airflow/models/taskinstance.py", line 733, in _execute_callable
    return ExecutionCallableRunner(
           ^^^^^^^^^^^^^^^^^^^^^^^^
  File "/home/airflow/.local/lib/python3.12/site-packages/airflow/utils/operator_helpers.py", line 252, in run
    return self.func(*args, **kwargs)
           ^^^^^^^^^^^^^^^^^^^^^^^^^^
  File "/home/airflow/.local/lib/python3.12/site-packages/airflow/models/baseoperator.py", line 422, in wrapper
    return func(self, *args, **kwargs)
           ^^^^^^^^^^^^^^^^^^^^^^^^^^^
  File "/home/airflow/.local/lib/python3.12/site-packages/airflow/operators/bash.py", line 276, in execute
    raise AirflowException(
airflow.exceptions.AirflowException: Bash command failed. The command returned a non-zero exit code 1.
[2025-02-09T18:36:21.097+0000] {local_task_job_runner.py:266} INFO - Task exited with return code 1
[2025-02-09T18:36:21.129+0000] {taskinstance.py:3895} INFO - 0 downstream tasks scheduled from follow-on schedule check
[2025-02-09T18:36:21.133+0000] {local_task_job_runner.py:245} INFO - ::endgroup::
